Workbook
Name timing_check: 'support-tickets'!$L:$L

Sheet Queue_Priority_1
A3: Count of ticket_id | B3: Column Labels
A4: Row Labels | B4: high | C4: low | D4: normal | E4: urgent | F4: Grand Total
A5: account | B5: 0.23802164 | C5: 0.22411128 | D5: 0.47913447 | E5: 0.058732612 | F5: 1
A6: billing | B6: 0.22395833 | C6: 0.209375 | D6: 0.47916667 | E6: 0.0875 | F6: 1
A7: integrations | B7: 0.19619048 | C7: 0.20952381 | D7: 0.52952381 | E7: 0.064761905 | F7: 1
A8: onboarding | B8: 0.23037543 | C8: 0.20648464 | D8: 0.47269625 | E8: 0.090443686 | F8: 1
A9: technical | B9: 0.23088924 | C9: 0.22386895 | D9: 0.47581903 | E9: 0.069422777 | F9: 1
A10: Grand Total | B10: 0.22575 | C10: 0.216 | D10: 0.48375 | E10: 0.0745 | F10: 1

Sheet Data_Checks
A1: Check | B1: Record count | C1: Missing %
A2: First response | B2: 149 | C2: 0.0373
A3: Resolution timestamp | B3: 225 | C3: 0.0563
A4: Satisfaction score | B4: 2774 | C4: 0.6935
A5: Numeric opening timestamps | B5: =COUNT(SupportTickets[opened_at]) -> 4000
A6: Numeric resolution timestamps | B6: =COUNT(SupportTickets[resolved_at]) -> 3775
A7: Timing records needing review. | B7: =COUNTIF('support-tickets'!L2:L4001,"Review") -> 143
A8: Rows with repeated ticket IDs | B8: =COUNTIF('support-tickets'!M2:M4001,">1") -> 0
A9: Negative first-response times | B9: =COUNTIF('support-tickets'!G2:G4001,"<0") -> 0
A10: Negative resolution hours | B10: =COUNTIF('support-tickets'!K2:K4001,"<0") -> 0
A11: CSAT scores outside 1–5 | B11: =COUNTIF(SupportTickets[csat],"<1")+COUNTIF(SupportTickets[csat],">5") -> 0
A14: Check | B14: Formula | C14: Expected
A15: Usable response times | B15: =COUNT('support-tickets'!N2:N4001) -> 3708 | C15: 3708
A16: Usable resolution times | B16: =COUNT('support-tickets'!O2:O4001) -> 3632 | C16: 3632
A21: x

Sheet support-tickets
A1: ticket_id | B1: opened_at | C1: channel | D1: queue | E1: priority | F1: subject | G1: first_response_min | H1: resolved_at | I1: reopened | J1: csat | K1: resolution_hours | L1: timing_check | M1: id_count | N1: analysis_first_response_min | O1: analysis_resolution_hours
A2: TK62871 | B2: 44927.094 | C2: in-app | D2: onboarding | E2: high | F2: Error when log in after password reset | G2: 63 | H2: 44927.324 | I2: TRUE | K2: =IF(H2="","",(H2-B2)*24) -> 5.5263889 | L2: =IF(OR(G2="",K2=""),"Cannot check",IF(G2>K2*60,"Review","OK")) -> OK | M2: =COUNTIF($A$2:$A$4001,A2) -> 1 | N2: =IF(OR(L2="Review",G2=""),"",G2) -> 63 | O2: =IF(OR(L2="Review",K2=""),"",K2) -> 5.5263889
A3: TK60343 | B3: 44927.237 | C3: email | D3: technical | E3: normal | F3: Question about two-factor authentication | G3: 7 | H3: 44927.381 | I3: FALSE | K3: =IF(H3="","",(H3-B3)*24) -> 3.4494444 | L3: =IF(OR(G3="",K3=""),"Cannot check",IF(G3>K3*60,"Review","OK")) -> OK | M3: =COUNTIF($A$2:$A$4001,A3) -> 1 | N3: =IF(OR(L3="Review",G3=""),"",G3) -> 7 | O3: =IF(OR(L3="Review",K3=""),"",K3) -> 3.4494444
A4: TK62950 | B4: 44927.253 | C4: in-app | D4: billing | E4: urgent | F4: Unable to connecting the Snowflake sync | G4: 44 | H4: 44927.343 | I4: FALSE | K4: =IF(H4="","",(H4-B4)*24) -> 2.1566667 | L4: =IF(OR(G4="",K4=""),"Cannot check",IF(G4>K4*60,"Review","OK")) -> OK | M4: =COUNTIF($A$2:$A$4001,A4) -> 1 | N4: =IF(OR(L4="Review",G4=""),"",G4) -> 44 | O4: =IF(OR(L4="Review",K4=""),"",K4) -> 2.1566667
A5: TK61014 | B5: 44927.272 | C5: chat | D5: integrations | E5: normal | F5: Cannot connecting the Snowflake sync | G5: 98 | I5: FALSE | K5: =IF(H5="","",(H5-B5)*24) | L5: =IF(OR(G5="",K5=""),"Cannot check",IF(G5>K5*60,"Review","OK")) -> Cannot check | M5: =COUNTIF($A$2:$A$4001,A5) -> 1 | N5: =IF(OR(L5="Review",G5=""),"",G5) -> 98 | O5: =IF(OR(L5="Review",K5=""),"",K5)
A6: TK61679 | B6: 44927.338 | C6: chat | D6: onboarding | E6: high | F6: How do I a duplicate charge | G6: 14 | H6: 44927.394 | I6: FALSE | J6: 5 | K6: =IF(H6="","",(H6-B6)*24) -> 1.3525 | L6: =IF(OR(G6="",K6=""),"Cannot check",IF(G6>K6*60,"Review","OK")) -> OK | M6: =COUNTIF($A$2:$A$4001,A6) -> 1 | N6: =IF(OR(L6="Review",G6=""),"",G6) -> 14 | O6: =IF(OR(L6="Review",K6=""),"",K6) -> 1.3525
A7: TK62374 | B7: 44927.353 | C7: in-app | D7: billing | E7: normal | F7: Issue with connecting the Snowflake sync | G7: 416 | H7: 44928.097 | I7: FALSE | J7: 3 | K7: =IF(H7="","",(H7-B7)*24) -> 17.864722 | L7: =IF(OR(G7="",K7=""),"Cannot check",IF(G7>K7*60,"Review","OK")) -> OK | M7: =COUNTIF($A$2:$A$4001,A7) -> 1 | N7: =IF(OR(L7="Review",G7=""),"",G7) -> 416 | O7: =IF(OR(L7="Review",K7=""),"",K7) -> 17.864722
A8: TK60058 | B8: 44927.606 | C8: in-app | D8: onboarding | E8: low | F8: Issue with connecting the Snowflake sync | G8: 361 | H8: 44927.779 | I8: FALSE | K8: =IF(H8="","",(H8-B8)*24) -> 4.1694444 | L8: =IF(OR(G8="",K8=""),"Cannot check",IF(G8>K8*60,"Review","OK")) -> Review | M8: =COUNTIF($A$2:$A$4001,A8) -> 1 | N8: =IF(OR(L8="Review",G8=""),"",G8) | O8: =IF(OR(L8="Review",K8=""),"",K8)
A9: TK63175 | B9: 44927.681 | C9: email | D9: billing | E9: high | F9: Request to a refund for an annual plan | G9: 52 | H9: 44927.865 | I9: FALSE | K9: =IF(H9="","",(H9-B9)*24) -> 4.4213889 | L9: =IF(OR(G9="",K9=""),"Cannot check",IF(G9>K9*60,"Review","OK")) -> OK | M9: =COUNTIF($A$2:$A$4001,A9) -> 1 | N9: =IF(OR(L9="Review",G9=""),"",G9) -> 52 | O9: =IF(OR(L9="Review",K9=""),"",K9) -> 4.4213889
A10: TK60862 | B10: 44927.838 | C10: chat | D10: technical | E10: urgent | F10: Unable to export my data | G10: 28 | H10: 44932.025 | I10: FALSE | K10: =IF(H10="","",(H10-B10)*24) -> 100.5025 | L10: =IF(OR(G10="",K10=""),"Cannot check",IF(G10>K10*60,"Review","OK")) -> OK | M10: =COUNTIF($A$2:$A$4001,A10) -> 1 | N10: =IF(OR(L10="Review",G10=""),"",G10) -> 28 | O10: =IF(OR(L10="Review",K10=""),"",K10) -> 100.5025
A11: TK61273 | B11: 44927.908 | C11: in-app | D11: billing | E11: urgent | F11: Unable to log in after password reset | H11: 44928.093 | I11: FALSE | K11: =IF(H11="","",(H11-B11)*24) -> 4.4388889 | L11: =IF(OR(G11="",K11=""),"Cannot check",IF(G11>K11*60,"Review","OK")) -> Cannot check | M11: =COUNTIF($A$2:$A$4001,A11) -> 1 | N11: =IF(OR(L11="Review",G11=""),"",G11) | O11: =IF(OR(L11="Review",K11=""),"",K11) -> 4.4388889
A12: TK60338 | B12: 44927.923 | C12: in-app | D12: integrations | E12: low | F12: Error when a duplicate charge | G12: 243 | H12: 44943.552 | I12: FALSE | K12: =IF(H12="","",(H12-B12)*24) -> 375.09028 | L12: =IF(OR(G12="",K12=""),"Cannot check",IF(G12>K12*60,"Review","OK")) -> OK | M12: =COUNTIF($A$2:$A$4001,A12) -> 1 | N12: =IF(OR(L12="Review",G12=""),"",G12) -> 243 | O12: =IF(OR(L12="Review",K12=""),"",K12) -> 375.09028
A13: TK62094 | B13: 44927.949 | C13: phone | D13: integrations | E13: high | F13: Question about downgrade my plan | G13: 19 | H13: 44928.919 | I13: TRUE | J13: 4 | K13: =IF(H13="","",(H13-B13)*24) -> 23.278333 | L13: =IF(OR(G13="",K13=""),"Cannot check",IF(G13>K13*60,"Review","OK")) -> OK | M13: =COUNTIF($A$2:$A$4001,A13) -> 1 | N13: =IF(OR(L13="Review",G13=""),"",G13) -> 19 | O13: =IF(OR(L13="Review",K13=""),"",K13) -> 23.278333
A14: TK61700 | B14: 44927.963 | C14: chat | D14: onboarding | E14: normal | F14: Error when downgrade my plan | G14: 109 | H14: 44928.571 | I14: FALSE | K14: =IF(H14="","",(H14-B14)*24) -> 14.589444 | L14: =IF(OR(G14="",K14=""),"Cannot check",IF(G14>K14*60,"Review","OK")) -> OK | M14: =COUNTIF($A$2:$A$4001,A14) -> 1 | N14: =IF(OR(L14="Review",G14=""),"",G14) -> 109 | O14: =IF(OR(L14="Review",K14=""),"",K14) -> 14.589444
A15: TK60629 | B15: 44928.021 | C15: phone | D15: technical | E15: normal | F15: Cannot the invoice for last month | G15: 135 | H15: 44932.013 | I15: FALSE | J15: 4 | K15: =IF(H15="","",(H15-B15)*24) -> 95.806944 | L15: =IF(OR(G15="",K15=""),"Cannot check",IF(G15>K15*60,"Review","OK")) -> OK | M15: =COUNTIF($A$2:$A$4001,A15) -> 1 | N15: =IF(OR(L15="Review",G15=""),"",G15) -> 135 | O15: =IF(OR(L15="Review",K15=""),"",K15) -> 95.806944
A16: TK61804 | B16: 44928.022 | C16: in-app | D16: technical | E16: low | F16: Request to downgrade my plan | G16: 34 | H16: 44935.485 | I16: TRUE | J16: 3 | K16: =IF(H16="","",(H16-B16)*24) -> 179.10972 | L16: =IF(OR(G16="",K16=""),"Cannot check",IF(G16>K16*60,"Review","OK")) -> OK | M16: =COUNTIF($A$2:$A$4001,A16) -> 1 | N16: =IF(OR(L16="Review",G16=""),"",G16) -> 34 | O16: =IF(OR(L16="Review",K16=""),"",K16) -> 179.10972
A17: TK63544 | B17: 44928.157 | C17: phone | D17: billing | E17: normal | F17: Question about the dashboard loading slowly | G17: 175 | H17: 44930.96 | I17: FALSE | K17: =IF(H17="","",(H17-B17)*24) -> 67.267222 | L17: =IF(OR(G17="",K17=""),"Cannot check",IF(G17>K17*60,"Review","OK")) -> OK | M17: =COUNTIF($A$2:$A$4001,A17) -> 1 | N17: =IF(OR(L17="Review",G17=""),"",G17) -> 175 | O17: =IF(OR(L17="Review",K17=""),"",K17) -> 67.267222
A18: TK60702 | B18: 44928.226 | C18: in-app | D18: billing | E18: normal | F18: Request to export my data | G18: 41 | H18: 44934.311 | I18: FALSE | K18: =IF(H18="","",(H18-B18)*24) -> 146.04111 | L18: =IF(OR(G18="",K18=""),"Cannot check",IF(G18>K18*60,"Review","OK")) -> OK | M18: =COUNTIF($A$2:$A$4001,A18) -> 1 | N18: =IF(OR(L18="Review",G18=""),"",G18) -> 41 | O18: =IF(OR(L18="Review",K18=""),"",K18) -> 146.04111
A19: TK63194 | B19: 44928.308 | C19: chat | D19: integrations | E19: normal | F19: Issue with connecting the Snowflake sync | G19: 16 | H19: 44928.921 | I19: FALSE | K19: =IF(H19="","",(H19-B19)*24) -> 14.718333 | L19: =IF(OR(G19="",K19=""),"Cannot check",IF(G19>K19*60,"Review","OK")) -> OK | M19: =COUNTIF($A$2:$A$4001,A19) -> 1 | N19: =IF(OR(L19="Review",G19=""),"",G19) -> 16 | O19: =IF(OR(L19="Review",K19=""),"",K19) -> 14.718333
A20: TK60986 | B20: 44928.412 | C20: chat | D20: onboarding | E20: normal | F20: Issue with add a teammate | G20: 125 | H20: 44931.054 | I20: FALSE | J20: 5 | K20: =IF(H20="","",(H20-B20)*24) -> 63.415 | L20: =IF(OR(G20="",K20=""),"Cannot check",IF(G20>K20*60,"Review","OK")) -> OK | M20: =COUNTIF($A$2:$A$4001,A20) -> 1 | N20: =IF(OR(L20="Review",G20=""),"",G20) -> 125 | O20: =IF(OR(L20="Review",K20=""),"",K20) -> 63.415
A21: TK60718 | B21: 44928.859 | C21: email | D21: account | E21: low | F21: Unable to a duplicate charge | G21: 127 | H21: 44930.399 | I21: FALSE | J21: 2 | K21: =IF(H21="","",(H21-B21)*24) -> 36.964722 | L21: =IF(OR(G21="",K21=""),"Cannot check",IF(G21>K21*60,"Review","OK")) -> OK | M21: =COUNTIF($A$2:$A$4001,A21) -> 1 | N21: =IF(OR(L21="Review",G21=""),"",G21) -> 127 | O21: =IF(OR(L21="Review",K21=""),"",K21) -> 36.964722
A22: TK62105 | B22: 44928.88 | C22: email | D22: account | E22: urgent | F22: Question about webhook deliveries failing | G22: 32 | H22: 44929.286 | I22: FALSE | J22: 3 | K22: =IF(H22="","",(H22-B22)*24) -> 9.7386111 | L22: =IF(OR(G22="",K22=""),"Cannot check",IF(G22>K22*60,"Review","OK")) -> OK | M22: =COUNTIF($A$2:$A$4001,A22) -> 1 | N22: =IF(OR(L22="Review",G22=""),"",G22) -> 32 | O22: =IF(OR(L22="Review",K22=""),"",K22) -> 9.7386111
A23: TK61752 | B23: 44928.894 | C23: in-app | D23: billing | E23: urgent | F23: Issue with a duplicate charge | G23: 9 | H23: 44929.539 | I23: FALSE | J23: 4 | K23: =IF(H23="","",(H23-B23)*24) -> 15.471667 | L23: =IF(OR(G23="",K23=""),"Cannot check",IF(G23>K23*60,"Review","OK")) -> OK | M23: =COUNTIF($A$2:$A$4001,A23) -> 1 | N23: =IF(OR(L23="Review",G23=""),"",G23) -> 9 | O23: =IF(OR(L23="Review",K23=""),"",K23) -> 15.471667
A24: TK63566 | B24: 44928.931 | C24: chat | D24: onboarding | E24: normal | F24: Issue with the dashboard loading slowly | G24: 58 | H24: 44929.346 | I24: TRUE | K24: =IF(H24="","",(H24-B24)*24) -> 9.9808333 | L24: =IF(OR(G24="",K24=""),"Cannot check",IF(G24>K24*60,"Review","OK")) -> OK | M24: =COUNTIF($A$2:$A$4001,A24) -> 1 | N24: =IF(OR(L24="Review",G24=""),"",G24) -> 58 | O24: =IF(OR(L24="Review",K24=""),"",K24) -> 9.9808333
A25: TK63266 | B25: 44929.026 | C25: email | D25: technical | E25: normal | F25: Request to the invoice for last month | G25: 46 | H25: 44929.494 | I25: FALSE | K25: =IF(H25="","",(H25-B25)*24) -> 11.223611 | L25: =IF(OR(G25="",K25=""),"Cannot check",IF(G25>K25*60,"Review","OK")) -> OK | M25: =COUNTIF($A$2:$A$4001,A25) -> 1 | N25: =IF(OR(L25="Review",G25=""),"",G25) -> 46 | O25: =IF(OR(L25="Review",K25=""),"",K25) -> 11.223611
A26: TK62379 | B26: 44929.03 | C26: chat | D26: account | E26: high | F26: Issue with the API rate limit | G26: 4 | H26: 44929.412 | I26: FALSE | K26: =IF(H26="","",(H26-B26)*24) -> 9.1636111 | L26: =IF(OR(G26="",K26=""),"Cannot check",IF(G26>K26*60,"Review","OK")) -> OK | M26: =COUNTIF($A$2:$A$4001,A26) -> 1 | N26: =IF(OR(L26="Review",G26=""),"",G26) -> 4 | O26: =IF(OR(L26="Review",K26=""),"",K26) -> 9.1636111
A27: TK63201 | B27: 44929.174 | C27: phone | D27: account | E27: normal | F27: How do I log in after password reset | G27: 47 | I27: FALSE | K27: =IF(H27="","",(H27-B27)*24) | L27: =IF(OR(G27="",K27=""),"Cannot check",IF(G27>K27*60,"Review","OK")) -> Cannot check | M27: =COUNTIF($A$2:$A$4001,A27) -> 1 | N27: =IF(OR(L27="Review",G27=""),"",G27) -> 47 | O27: =IF(OR(L27="Review",K27=""),"",K27)
A28: TK63493 | B28: 44929.2 | C28: chat | D28: account | E28: normal | F28: Unable to the invoice for last month | G28: 78 | H28: 44930.417 | I28: FALSE | K28: =IF(H28="","",(H28-B28)*24) -> 29.196389 | L28: =IF(OR(G28="",K28=""),"Cannot check",IF(G28>K28*60,"Review","OK")) -> OK | M28: =COUNTIF($A$2:$A$4001,A28) -> 1 | N28: =IF(OR(L28="Review",G28=""),"",G28) -> 78 | O28: =IF(OR(L28="Review",K28=""),"",K28) -> 29.196389
A29: TK61552 | B29: 44929.372 | C29: in-app | D29: technical | E29: normal | F29: Request to webhook deliveries failing | G29: 285 | H29: 44930.517 | I29: TRUE | K29: =IF(H29="","",(H29-B29)*24) -> 27.467222 | L29: =IF(OR(G29="",K29=""),"Cannot check",IF(G29>K29*60,"Review","OK")) -> OK | M29: =COUNTIF($A$2:$A$4001,A29) -> 1 | N29: =IF(OR(L29="Review",G29=""),"",G29) -> 285 | O29: =IF(OR(L29="Review",K29=""),"",K29) -> 27.467222
A30: TK62963 | B30: 44929.424 | C30: chat | D30: account | E30: high | F30: How do I the API rate limit | G30: 19 | H30: 44929.758 | I30: FALSE | K30: =IF(H30="","",(H30-B30)*24) -> 8.01 | L30: =IF(OR(G30="",K30=""),"Cannot check",IF(G30>K30*60,"Review","OK")) -> OK | M30: =COUNTIF($A$2:$A$4001,A30) -> 1 | N30: =IF(OR(L30="Review",G30=""),"",G30) -> 19 | O30: =IF(OR(L30="Review",K30=""),"",K30) -> 8.01
A31: TK61844 | B31: 44929.434 | C31: chat | D31: billing | E31: high | F31: Error when export my data | G31: 32 | H31: 44929.509 | I31: FALSE | K31: =IF(H31="","",(H31-B31)*24) -> 1.8075 | L31: =IF(OR(G31="",K31=""),"Cannot check",IF(G31>K31*60,"Review","OK")) -> OK | M31: =COUNTIF($A$2:$A$4001,A31) -> 1 | N31: =IF(OR(L31="Review",G31=""),"",G31) -> 32 | O31: =IF(OR(L31="Review",K31=""),"",K31) -> 1.8075
A32: TK62478 | B32: 44929.45 | C32: email | D32: billing | E32: normal | F32: How do I the API rate limit | G32: 103 | H32: 44930.163 | I32: FALSE | K32: =IF(H32="","",(H32-B32)*24) -> 17.123611 | L32: =IF(OR(G32="",K32=""),"Cannot check",IF(G32>K32*60,"Review","OK")) -> OK | M32: =COUNTIF($A$2:$A$4001,A32) -> 1 | N32: =IF(OR(L32="Review",G32=""),"",G32) -> 103 | O32: =IF(OR(L32="Review",K32=""),"",K32) -> 17.123611
A33: TK60108 | B33: 44929.464 | C33: email | D33: billing | E33: low | F33: Error when export my data | G33: 137 | H33: 44931.376 | I33: FALSE | J33: 5 | K33: =IF(H33="","",(H33-B33)*24) -> 45.9025 | L33: =IF(OR(G33="",K33=""),"Cannot check",IF(G33>K33*60,"Review","OK")) -> OK | M33: =COUNTIF($A$2:$A$4001,A33) -> 1 | N33: =IF(OR(L33="Review",G33=""),"",G33) -> 137 | O33: =IF(OR(L33="Review",K33=""),"",K33) -> 45.9025
A34: TK63111 | B34: 44929.54 | C34: chat | D34: technical | E34: high | F34: Error when a refund for an annual plan | G34: 19 | H34: 44930.433 | I34: FALSE | K34: =IF(H34="","",(H34-B34)*24) -> 21.433611 | L34: =IF(OR(G34="",K34=""),"Cannot check",IF(G34>K34*60,"Review","OK")) -> OK | M34: =COUNTIF($A$2:$A$4001,A34) -> 1 | N34: =IF(OR(L34="Review",G34=""),"",G34) -> 19 | O34: =IF(OR(L34="Review",K34=""),"",K34) -> 21.433611
A35: TK61543 | B35: 44929.544 | C35: in-app | D35: technical | E35: normal | F35: Cannot the API rate limit | G35: 368 | H35: 44929.83 | I35: FALSE | J35: 4 | K35: =IF(H35="","",(H35-B35)*24) -> 6.8466667 | L35: =IF(OR(G35="",K35=""),"Cannot check",IF(G35>K35*60,"Review","OK")) -> OK | M35: =COUNTIF($A$2:$A$4001,A35) -> 1 | N35: =IF(OR(L35="Review",G35=""),"",G35) -> 368 | O35: =IF(OR(L35="Review",K35=""),"",K35) -> 6.8466667
A36: TK61064 | B36: 44929.56 | C36: phone | D36: technical | E36: normal | F36: Request to a duplicate charge | G36: 106 | H36: 44930.613 | I36: FALSE | J36: 4 | K36: =IF(H36="","",(H36-B36)*24) -> 25.255833 | L36: =IF(OR(G36="",K36=""),"Cannot check",IF(G36>K36*60,"Review","OK")) -> OK | M36: =COUNTIF($A$2:$A$4001,A36) -> 1 | N36: =IF(OR(L36="Review",G36=""),"",G36) -> 106 | O36: =IF(OR(L36="Review",K36=""),"",K36) -> 25.255833
A37: TK62588 | B37: 44929.576 | C37: email | D37: account | E37: low | F37: Unable to two-factor authentication | G37: 98 | H37: 44932.826 | I37: FALSE | K37: =IF(H37="","",(H37-B37)*24) -> 77.998889 | L37: =IF(OR(G37="",K37=""),"Cannot check",IF(G37>K37*60,"Review","OK")) -> OK | M37: =COUNTIF($A$2:$A$4001,A37) -> 1 | N37: =IF(OR(L37="Review",G37=""),"",G37) -> 98 | O37: =IF(OR(L37="Review",K37=""),"",K37) -> 77.998889
A38: TK62293 | B38: 44929.718 | C38: email | D38: account | E38: low | F38: Question about a duplicate charge | G38: 221 | H38: 44930.891 | I38: FALSE | K38: =IF(H38="","",(H38-B38)*24) -> 28.161944 | L38: =IF(OR(G38="",K38=""),"Cannot check",IF(G38>K38*60,"Review","OK")) -> OK | M38: =COUNTIF($A$2:$A$4001,A38) -> 1 | N38: =IF(OR(L38="Review",G38=""),"",G38) -> 221 | O38: =IF(OR(L38="Review",K38=""),"",K38) -> 28.161944
A39: TK61772 | B39: 44929.73 | C39: chat | D39: integrations | E39: normal | F39: Request to connecting the Snowflake sync | G39: 30 | H39: 44930.795 | I39: FALSE | K39: =IF(H39="","",(H39-B39)*24) -> 25.5525 | L39: =IF(OR(G39="",K39=""),"Cannot check",IF(G39>K39*60,"Review","OK")) -> OK | M39: =COUNTIF($A$2:$A$4001,A39) -> 1 | N39: =IF(OR(L39="Review",G39=""),"",G39) -> 30 | O39: =IF(OR(L39="Review",K39=""),"",K39) -> 25.5525
A40: TK63162 | B40: 44929.738 | C40: email | D40: technical | E40: normal | F40: Issue with downgrade my plan | G40: 204 | H40: 44938.744 | I40: FALSE | K40: =IF(H40="","",(H40-B40)*24) -> 216.14861 | L40: =IF(OR(G40="",K40=""),"Cannot check",IF(G40>K40*60,"Review","OK")) -> OK | M40: =COUNTIF($A$2:$A$4001,A40) -> 1 | N40: =IF(OR(L40="Review",G40=""),"",G40) -> 204 | O40: =IF(OR(L40="Review",K40=""),"",K40) -> 216.14861
...

Sheet Queue_Summary
A3: Row Labels | B3: Count of ticket_id | C3: Count of ticket_id2
A4: technical | B4: 1282 | C4: 0.3205
A5: billing | B5: 960 | C5: 0.24
A6: account | B6: 647 | C6: 0.16175
A7: onboarding | B7: 586 | C7: 0.1465
A8: integrations | B8: 525 | C8: 0.13125
A9: Grand Total | B9: 4000 | C9: 1
A8005: =SUM(A3:A8005) -> 0

Sheet Cleaning_Notes
A1: Issue | B1: Decision
A2: 149 = missing first-response times | B2: Keep blank; exclude from average first-response time.
A3: 225 = missing resolution timestamps | B3: Keep blank; exclude from average resolution time.
A4: 2,774 = missing satisfaction scores | B4: Keep blank; calculate average CSAT using recorded scores only.
A5: 143 = timing inconsistencies | B5: Keep records flagged for review; do notPreserved original values. Excluded 143 conflicting tickets from timing metrics using the analysis columns. Retained them for ticket counts. Correct times remain unknown. alter durations without evidence.
A7: Cell | B7: Enter
A8: A8 | B8: Initial findings
A9: A9 | B9: Technical has the largest ticket volume: 1,282 tickets (32.05%).
A10: A10 | B10: Technical and billing together account for 56.05% of tickets.
A11: A11 | B11: Only 1,226 of 4,000 tickets have CSAT scores (30.65%); satisfaction findings represent rated tickets.
A12: A12 | B12: Ticket volume alone does not show which queue performs poorly; response and resolution times need analysis.

Sheet Charts
A1: Queue | B1: Ticket count
A2: technical | B2: 1282
A3: billing | B3: 960
A4: account | B4: 647
A5: onboarding | B5: 586
A6: integrations | B6: 525
